<?xml version="1.0" encoding="UTF-8"?>
<!-- Generated by org.testng.reporters.JUnitXMLReporter -->
<testsuite hostname="admin" name="test" tests="4" failures="2" timestamp="23 Apr 2019 15:22:53 GMT" time="0.114" errors="0">
  <testcase name="test1" time="0.038" classname="com.zym.demo.TestMethodsDemo">
    <failure type="java.lang.AssertionError" message="expected [2] but found [1]">
      <![CDATA[java.lang.AssertionError: expected [2] but found [1]
	at com.zym.demo.TestMethodsDemo.test1(TestMethodsDemo.java:11)
... Removed 29 stack frames]]>
    </failure>
  </testcase> <!-- test1 -->
  <testcase name="test2" time="0.005" classname="com.zym.demo.TestMethodsDemo"/>
  <testcase name="test3" time="0.004" classname="com.zym.demo.TestMethodsDemo"/>
  <testcase name="logDemo" time="0.004" classname="com.zym.demo.TestMethodsDemo">
    <failure type="java.lang.RuntimeException" message="这是我们自己的运行时异常">
      <![CDATA[java.lang.RuntimeException: 这是我们自己的运行时异常
	at com.zym.demo.TestMethodsDemo.logDemo(TestMethodsDemo.java:24)
... Removed 24 stack frames]]>
    </failure>
  </testcase> <!-- logDemo -->
</testsuite> <!-- test -->
